2024-11-01 10:47:48,106 [INFO] __main__: DataChannel created, state: connecting
2024-11-01 10:47:48,696 [INFO] __main__: Connected to signaling server
2024-11-01 10:47:48,773 [INFO] __main__: Offer sent to connector
2024-11-01 10:47:48,970 [INFO] __main__: Received answer from connector
2024-11-01 10:47:48,971 [INFO] __main__: ICE connection state: checking
2024-11-01 10:48:52,803 [INFO] __main__: ICE connection state: failed
2024-11-01 10:48:52,803 [ERROR] __main__: ICE connection failed, attempting reset
2024-11-01 10:48:52,804 [INFO] __main__: ICE connection state: closed
2024-11-01 10:48:52,806 [INFO] __main__: DataChannel created, state: connecting
2024-11-01 10:48:53,417 [INFO] __main__: Connected to signaling server
2024-11-01 10:48:53,487 [INFO] __main__: Offer sent to connector
2024-11-01 10:48:53,697 [INFO] __main__: Received answer from connector
2024-11-01 10:48:53,698 [INFO] __main__: ICE connection state: checking
2024-11-01 10:49:57,578 [INFO] __main__: ICE connection state: failed
2024-11-01 10:49:57,579 [ERROR] __main__: ICE connection failed, attempting reset
2024-11-01 10:49:57,579 [INFO] __main__: ICE connection state: closed
2024-11-01 10:49:57,581 [INFO] __main__: DataChannel created, state: connecting
2024-11-01 10:49:58,150 [INFO] __main__: Connected to signaling server
2024-11-01 10:49:58,220 [INFO] __main__: Offer sent to connector
2024-11-01 10:49:58,414 [INFO] __main__: Received answer from connector
2024-11-01 10:49:58,415 [INFO] __main__: ICE connection state: checking
2024-11-01 10:50:31,144 [INFO] __main__: DataChannel created, state: connecting
2024-11-01 10:50:31,764 [INFO] __main__: Connected to signaling server
2024-11-01 10:50:31,842 [INFO] __main__: Offer sent to connector
2024-11-01 10:50:32,052 [INFO] __main__: Received answer from connector
2024-11-01 10:50:32,053 [INFO] __main__: ICE connection state: checking
2024-11-01 10:50:32,521 [INFO] __main__: ICE connection state: completed
2024-11-01 10:50:33,498 [INFO] __main__: DataChannel is now open
2024-11-01 10:50:33,499 [INFO] __main__: Interacting with Connector
2024-11-01 11:08:19,031 [ERROR] asyncio: Task exception was never retrieved
future: <Task finished name='Task-35' coro=<Client.interact_with_connector() done, defined at C:\Users\ASUS\OneDrive\Desktop\capstone1\ztatest1\client\client.py:187> exception=EOFError()>
Traceback (most recent call last):
  File "C:\Users\ASUS\OneDrive\Desktop\capstone1\ztatest1\client\client.py", line 194, in interact_with_connector
    choice = await aioconsole.ainput("Select an action: ")
             ^^^^^^^^^^^^^^^^^^^^^^^^^^^^^^^^^^^^^^^^^^^^^
  File "C:\Users\ASUS\AppData\Local\Programs\Python\Python311\Lib\site-packages\aioconsole\stream.py", line 297, in ainput
    raise EOFError
EOFError
2024-11-01 11:08:19,234 [INFO] __main__: DataChannel closed
2024-11-01 11:08:19,234 [INFO] __main__: ICE connection state: closed
2024-11-01 11:14:54,367 [INFO] __main__: DataChannel created, state: connecting
2024-11-01 11:14:54,981 [INFO] __main__: Connected to signaling server
2024-11-01 11:15:00,004 [INFO] __main__: Offer sent to connector
2024-11-01 11:15:00,056 [ERROR] asyncio: Unclosed client session
client_session: <aiohttp.client.ClientSession object at 0x000001D90818C210>
2024-11-01 11:15:19,704 [INFO] __main__: DataChannel created, state: connecting
2024-11-01 11:15:20,298 [INFO] __main__: Connected to signaling server
2024-11-01 11:15:25,319 [INFO] __main__: Offer sent to connector
2024-11-01 11:15:25,322 [INFO] __main__: Closed aiohttp session
2024-11-01 11:16:44,123 [INFO] __main__: DataChannel created, state: connecting
2024-11-01 11:16:44,132 [INFO] __main__: Connected to signaling server
2024-11-01 11:16:49,143 [INFO] __main__: Offer sent to connector
2024-11-01 11:16:49,146 [INFO] __main__: Closed aiohttp session
2024-11-01 11:19:31,766 [INFO] __main__: DataChannel created, state: connecting
2024-11-01 11:19:31,778 [INFO] __main__: Connected to signaling server
2024-11-01 11:19:36,805 [INFO] __main__: Offer sent to connector
2024-11-01 11:19:36,808 [INFO] __main__: Closed aiohttp session
2024-11-01 11:21:34,817 [INFO] __main__: DataChannel created, state: connecting
2024-11-01 11:21:34,826 [INFO] __main__: Connected to signaling server
2024-11-01 11:21:39,851 [INFO] __main__: Offer sent to connector
2024-11-01 11:22:41,396 [INFO] __main__: Closed aiohttp session
2024-11-01 11:22:43,188 [INFO] __main__: DataChannel created, state: connecting
2024-11-01 11:22:43,197 [INFO] __main__: Connected to signaling server
2024-11-01 11:22:48,205 [INFO] __main__: Offer sent to connector
2024-11-01 11:22:48,207 [ERROR] __main__: peer_info is missing 'ip' or 'port'
2024-11-01 11:22:53,228 [INFO] __main__: Received answer from connector
2024-11-01 11:22:53,229 [INFO] __main__: ICE connection state: checking
2024-11-01 11:22:53,256 [INFO] __main__: ICE connection state: completed
2024-11-01 11:22:53,262 [INFO] __main__: DataChannel is open
2024-11-01 11:22:53,263 [INFO] __main__: Interacting with Connector
2024-11-01 11:23:59,078 [INFO] __main__: Closed aiohttp session
2024-11-01 11:23:59,079 [ERROR] asyncio: Task exception was never retrieved
future: <Task finished name='Task-29' coro=<Client.interact_with_connector() done, defined at C:\Users\ASUS\OneDrive\Desktop\capstone1\ztatest1\client\client1.py:262> exception=EOFError()>
Traceback (most recent call last):
  File "C:\Users\ASUS\OneDrive\Desktop\capstone1\ztatest1\client\client1.py", line 269, in interact_with_connector
    choice = await aioconsole.ainput("Select an action: ")
             ^^^^^^^^^^^^^^^^^^^^^^^^^^^^^^^^^^^^^^^^^^^^^
  File "C:\Users\ASUS\AppData\Local\Programs\Python\Python311\Lib\site-packages\aioconsole\stream.py", line 297, in ainput
    raise EOFError
EOFError
2024-11-01 11:23:59,081 [INFO] __main__: ICE connection state: closed
2024-11-01 11:24:19,933 [INFO] __main__: DataChannel created, state: connecting
2024-11-01 11:24:19,942 [INFO] __main__: Connected to signaling server
2024-11-01 11:24:24,961 [INFO] __main__: Offer sent to connector
2024-11-01 11:24:24,963 [ERROR] __main__: peer_info is missing 'ip' or 'port'
2024-11-01 11:24:29,981 [INFO] __main__: Received answer from connector
2024-11-01 11:24:29,982 [INFO] __main__: ICE connection state: checking
2024-11-01 11:24:30,009 [INFO] __main__: ICE connection state: completed
2024-11-01 11:24:30,015 [INFO] __main__: DataChannel is open
2024-11-01 11:24:30,016 [INFO] __main__: Interacting with Connector
2024-11-01 11:25:04,390 [INFO] __main__: ICE connection state: closed
2024-11-01 11:25:10,763 [ERROR] asyncio: Task exception was never retrieved
future: <Task finished name='Task-29' coro=<Client.interact_with_connector() done, defined at C:\Users\ASUS\OneDrive\Desktop\capstone1\ztatest1\client\client1.py:262> exception=InvalidStateError()>
Traceback (most recent call last):
  File "C:\Users\ASUS\OneDrive\Desktop\capstone1\ztatest1\client\client1.py", line 273, in interact_with_connector
    self.channel.send(json.dumps(request))
  File "C:\Users\ASUS\AppData\Local\Programs\Python\Python311\Lib\site-packages\aiortc\rtcdatachannel.py", line 182, in send
    raise InvalidStateError
aiortc.exceptions.InvalidStateError
2024-11-01 11:25:12,762 [INFO] __main__: Closed aiohttp session
2024-11-01 11:29:09,806 [INFO] __main__: DataChannel created, state: connecting
2024-11-01 11:29:10,418 [INFO] __main__: Connected to signaling server
2024-11-01 11:29:15,446 [INFO] __main__: Offer sent to connector
2024-11-01 11:29:15,648 [ERROR] __main__: peer_info is missing 'ip' or 'port'
2024-11-01 11:29:15,659 [INFO] __main__: Received answer from connector
2024-11-01 11:29:15,660 [INFO] __main__: ICE connection state: checking
2024-11-01 11:30:19,487 [INFO] __main__: ICE connection state: failed
2024-11-01 11:30:19,488 [ERROR] __main__: ICE connection failed, attempting reset
2024-11-01 11:30:19,489 [INFO] __main__: ICE connection state: closed
2024-11-01 11:30:19,491 [INFO] __main__: DataChannel created, state: connecting
2024-11-01 11:30:20,105 [INFO] __main__: Connected to signaling server
2024-11-01 11:30:25,109 [INFO] __main__: Offer sent to connector
2024-11-01 11:30:25,311 [ERROR] __main__: peer_info is missing 'ip' or 'port'
2024-11-01 11:30:25,318 [INFO] __main__: Received answer from connector
2024-11-01 11:30:25,318 [INFO] __main__: ICE connection state: checking
2024-11-01 11:31:29,154 [INFO] __main__: ICE connection state: failed
2024-11-01 11:31:29,155 [ERROR] __main__: ICE connection failed, attempting reset
2024-11-01 11:31:29,156 [INFO] __main__: ICE connection state: closed
2024-11-01 11:31:29,158 [INFO] __main__: DataChannel created, state: connecting
2024-11-01 11:31:29,746 [INFO] __main__: Connected to signaling server
2024-11-01 11:31:34,746 [INFO] __main__: Offer sent to connector
2024-11-01 11:31:34,941 [ERROR] __main__: peer_info is missing 'ip' or 'port'
2024-11-01 11:31:34,946 [INFO] __main__: Received answer from connector
2024-11-01 11:31:34,947 [INFO] __main__: ICE connection state: checking
2024-11-01 11:32:38,819 [INFO] __main__: ICE connection state: failed
2024-11-01 11:32:38,820 [ERROR] __main__: ICE connection failed, attempting reset
2024-11-01 11:32:38,821 [INFO] __main__: ICE connection state: closed
2024-11-01 11:32:38,823 [INFO] __main__: DataChannel created, state: connecting
2024-11-01 11:32:39,412 [INFO] __main__: Connected to signaling server
2024-11-01 11:32:44,434 [INFO] __main__: Offer sent to connector
2024-11-01 11:32:44,630 [ERROR] __main__: peer_info is missing 'ip' or 'port'
2024-11-01 11:32:44,636 [INFO] __main__: Received answer from connector
2024-11-01 11:32:44,637 [INFO] __main__: ICE connection state: checking
2024-11-01 11:33:48,479 [INFO] __main__: ICE connection state: failed
2024-11-01 11:33:48,480 [ERROR] __main__: ICE connection failed, attempting reset
2024-11-01 11:33:48,481 [INFO] __main__: ICE connection state: closed
2024-11-01 11:33:48,483 [INFO] __main__: DataChannel created, state: connecting
2024-11-01 11:33:49,097 [INFO] __main__: Connected to signaling server
2024-11-01 11:33:54,107 [INFO] __main__: Offer sent to connector
2024-11-01 11:33:54,312 [ERROR] __main__: peer_info is missing 'ip' or 'port'
2024-11-01 11:33:54,314 [INFO] __main__: Received answer from connector
2024-11-01 11:33:54,315 [INFO] __main__: ICE connection state: checking
2024-11-01 11:34:05,260 [INFO] __main__: Closed aiohttp session
2024-11-01 11:34:05,261 [INFO] __main__: Closed aiohttp session
2024-11-01 11:34:05,261 [INFO] __main__: Closed aiohttp session
2024-11-01 11:34:05,263 [INFO] __main__: Closed aiohttp session
2024-11-01 11:34:05,263 [INFO] __main__: Closed aiohttp session
2024-11-01 11:34:05,264 [ERROR] asyncio: Unclosed client session
client_session: <aiohttp.client.ClientSession object at 0x00000204A6900590>
2024-11-01 11:34:05,265 [ERROR] asyncio: Unclosed client session
client_session: <aiohttp.client.ClientSession object at 0x00000204A6900350>
2024-11-01 11:34:05,266 [ERROR] asyncio: Unclosed client session
client_session: <aiohttp.client.ClientSession object at 0x00000204A6A45550>
2024-11-01 11:34:05,320 [ERROR] asyncio: Unclosed client session
client_session: <aiohttp.client.ClientSession object at 0x00000204A6964190>
2024-11-01 11:34:34,196 [INFO] __main__: DataChannel created, state: connecting
2024-11-01 11:34:34,204 [INFO] __main__: Connected to signaling server
2024-11-01 11:34:39,234 [INFO] __main__: Offer sent to connector
2024-11-01 11:34:44,246 [INFO] __main__: Received answer from connector
2024-11-01 11:34:44,247 [INFO] __main__: ICE connection state: checking
2024-11-01 11:34:44,277 [INFO] __main__: ICE connection state: completed
2024-11-01 11:34:44,282 [INFO] __main__: DataChannel is open
2024-11-01 11:34:44,283 [INFO] __main__: Interacting with Connector
2024-11-01 11:36:55,188 [INFO] __main__: Closed aiohttp session
2024-11-01 11:36:55,188 [ERROR] asyncio: Task exception was never retrieved
future: <Task finished name='Task-29' coro=<Client.interact_with_connector() done, defined at C:\Users\ASUS\OneDrive\Desktop\capstone1\ztatest1\client\client1.py:262> exception=EOFError()>
Traceback (most recent call last):
  File "C:\Users\ASUS\OneDrive\Desktop\capstone1\ztatest1\client\client1.py", line 269, in interact_with_connector
    choice = await aioconsole.ainput("Select an action: ")
             ^^^^^^^^^^^^^^^^^^^^^^^^^^^^^^^^^^^^^^^^^^^^^
  File "C:\Users\ASUS\AppData\Local\Programs\Python\Python311\Lib\site-packages\aioconsole\stream.py", line 297, in ainput
    raise EOFError
EOFError
2024-11-01 11:36:55,202 [INFO] __main__: ICE connection state: closed
2024-11-01 11:37:09,611 [INFO] __main__: DataChannel created, state: connecting
2024-11-01 11:37:09,619 [INFO] __main__: Connected to signaling server
2024-11-01 11:37:14,628 [INFO] __main__: Offer sent to connector
2024-11-01 11:37:19,638 [INFO] __main__: Received answer from connector
2024-11-01 11:37:19,640 [INFO] __main__: ICE connection state: checking
2024-11-01 11:37:19,669 [INFO] __main__: ICE connection state: completed
2024-11-01 11:37:19,674 [INFO] __main__: DataChannel is open
2024-11-01 11:37:19,675 [INFO] __main__: Interacting with Connector
2024-11-01 11:40:11,828 [INFO] __main__: Closed aiohttp session
2024-11-01 11:40:11,829 [ERROR] asyncio: Task exception was never retrieved
future: <Task finished name='Task-29' coro=<Client.interact_with_connector() done, defined at C:\Users\ASUS\OneDrive\Desktop\capstone1\ztatest1\client\client1.py:262> exception=EOFError()>
Traceback (most recent call last):
  File "C:\Users\ASUS\OneDrive\Desktop\capstone1\ztatest1\client\client1.py", line 269, in interact_with_connector
    choice = await aioconsole.ainput("Select an action: ")
             ^^^^^^^^^^^^^^^^^^^^^^^^^^^^^^^^^^^^^^^^^^^^^
  File "C:\Users\ASUS\AppData\Local\Programs\Python\Python311\Lib\site-packages\aioconsole\stream.py", line 297, in ainput
    raise EOFError
EOFError
2024-11-01 11:40:11,832 [INFO] __main__: ICE connection state: closed
2024-11-01 11:40:14,070 [INFO] __main__: DataChannel created, state: connecting
2024-11-01 11:40:14,668 [INFO] __main__: Connected to signaling server
2024-11-01 11:40:19,698 [INFO] __main__: Offer sent to connector
2024-11-01 11:40:19,902 [INFO] __main__: Received answer from connector
2024-11-01 11:40:19,903 [INFO] __main__: ICE connection state: checking
2024-11-01 11:41:23,749 [INFO] __main__: ICE connection state: failed
2024-11-01 11:41:23,750 [ERROR] __main__: ICE connection failed, attempting reset
2024-11-01 11:41:23,751 [INFO] __main__: ICE connection state: closed
2024-11-01 11:41:23,753 [INFO] __main__: DataChannel created, state: connecting
2024-11-01 11:41:24,366 [INFO] __main__: Connected to signaling server
2024-11-01 11:41:29,379 [INFO] __main__: Offer sent to connector
2024-11-01 11:41:29,585 [INFO] __main__: Received answer from connector
2024-11-01 11:41:29,588 [INFO] __main__: ICE connection state: checking
2024-11-01 11:42:33,438 [INFO] __main__: ICE connection state: failed
2024-11-01 11:42:33,439 [ERROR] __main__: ICE connection failed, attempting reset
2024-11-01 11:42:33,439 [INFO] __main__: ICE connection state: closed
2024-11-01 11:42:33,441 [INFO] __main__: DataChannel created, state: connecting
2024-11-01 11:42:34,048 [INFO] __main__: Connected to signaling server
2024-11-01 11:42:39,067 [INFO] __main__: Offer sent to connector
2024-11-01 11:42:39,273 [INFO] __main__: Received answer from connector
2024-11-01 11:42:39,274 [INFO] __main__: ICE connection state: checking
2024-11-01 11:43:43,149 [INFO] __main__: ICE connection state: failed
2024-11-01 11:43:43,150 [ERROR] __main__: ICE connection failed, attempting reset
2024-11-01 11:43:43,150 [INFO] __main__: ICE connection state: closed
2024-11-01 11:43:43,153 [INFO] __main__: DataChannel created, state: connecting
2024-11-01 11:43:43,741 [INFO] __main__: Connected to signaling server
2024-11-01 11:43:48,755 [INFO] __main__: Offer sent to connector
2024-11-01 11:43:48,960 [INFO] __main__: Received answer from connector
2024-11-01 11:43:48,961 [INFO] __main__: ICE connection state: checking
2024-11-01 11:44:52,839 [INFO] __main__: ICE connection state: failed
2024-11-01 11:44:52,839 [ERROR] __main__: ICE connection failed, attempting reset
2024-11-01 11:44:52,840 [INFO] __main__: ICE connection state: closed
2024-11-01 11:44:52,841 [INFO] __main__: DataChannel created, state: connecting
2024-11-01 11:44:53,435 [INFO] __main__: Connected to signaling server
2024-11-01 11:44:58,436 [INFO] __main__: Offer sent to connector
2024-11-01 11:44:58,637 [INFO] __main__: Received answer from connector
2024-11-01 11:44:58,638 [INFO] __main__: ICE connection state: checking
2024-11-01 11:46:02,498 [INFO] __main__: ICE connection state: failed
2024-11-01 11:46:02,499 [ERROR] __main__: ICE connection failed, attempting reset
2024-11-01 11:46:02,500 [INFO] __main__: ICE connection state: closed
2024-11-01 11:46:02,503 [INFO] __main__: DataChannel created, state: connecting
2024-11-01 11:46:03,114 [INFO] __main__: Connected to signaling server
2024-11-01 11:46:08,131 [INFO] __main__: Offer sent to connector
2024-11-01 11:46:08,341 [INFO] __main__: Received answer from connector
2024-11-01 11:46:08,343 [INFO] __main__: ICE connection state: checking
2024-11-01 11:47:09,513 [INFO] __main__: Closed aiohttp session
2024-11-01 11:47:09,514 [INFO] __main__: Closed aiohttp session
2024-11-01 11:47:09,515 [INFO] __main__: Closed aiohttp session
2024-11-01 11:47:09,515 [INFO] __main__: Closed aiohttp session
2024-11-01 11:47:09,516 [INFO] __main__: Closed aiohttp session
2024-11-01 11:47:09,516 [INFO] __main__: Closed aiohttp session
2024-11-01 11:47:09,517 [ERROR] asyncio: Unclosed client session
client_session: <aiohttp.client.ClientSession object at 0x000001F3680C4350>
2024-11-01 11:47:09,517 [ERROR] asyncio: Unclosed client session
client_session: <aiohttp.client.ClientSession object at 0x000001F36809F0D0>
2024-11-01 11:47:09,518 [ERROR] asyncio: Unclosed client session
client_session: <aiohttp.client.ClientSession object at 0x000001F3680FE090>
2024-11-01 11:47:09,519 [ERROR] asyncio: Unclosed client session
client_session: <aiohttp.client.ClientSession object at 0x000001F3681FD710>
2024-11-01 11:47:09,570 [ERROR] asyncio: Unclosed client session
client_session: <aiohttp.client.ClientSession object at 0x000001F3680D8450>
2024-11-01 12:05:16,408 [INFO] __main__: DataChannel created, state: connecting
2024-11-01 12:05:16,418 [INFO] __main__: Connected to signaling server
2024-11-01 12:06:24,985 [INFO] __main__: Closed aiohttp session
2024-11-01 12:06:37,466 [INFO] __main__: DataChannel created, state: connecting
2024-11-01 12:06:37,475 [INFO] __main__: Connected to signaling server
2024-11-01 12:06:42,477 [INFO] __main__: Offer sent to connector
2024-11-01 12:06:47,490 [INFO] __main__: Received answer from connector
2024-11-01 12:06:47,491 [INFO] __main__: ICE connection state: checking
2024-11-01 12:06:47,519 [INFO] __main__: ICE connection state: completed
2024-11-01 12:06:47,524 [INFO] __main__: DataChannel is open
2024-11-01 12:06:47,525 [INFO] __main__: Interacting with Connector
2024-11-01 12:16:25,360 [INFO] __main__: Closed aiohttp session
2024-11-01 12:16:25,361 [ERROR] asyncio: Task exception was never retrieved
future: <Task finished name='Task-29' coro=<Client.interact_with_connector() done, defined at C:\Users\ASUS\OneDrive\Desktop\capstone1\ztatest1\client\client1.py:263> exception=EOFError()>
Traceback (most recent call last):
  File "C:\Users\ASUS\OneDrive\Desktop\capstone1\ztatest1\client\client1.py", line 270, in interact_with_connector
  File "C:\Users\ASUS\AppData\Local\Programs\Python\Python311\Lib\site-packages\aioconsole\stream.py", line 297, in ainput
    raise EOFError
EOFError
2024-11-01 12:16:25,374 [INFO] __main__: ICE connection state: closed
2024-11-01 12:16:56,497 [INFO] __main__: DataChannel created, state: connecting
2024-11-01 12:16:56,506 [INFO] __main__: Connected to signaling server
2024-11-01 12:17:01,696 [INFO] __main__: Offer sent to connector
2024-11-01 12:17:06,880 [INFO] __main__: Received answer from connector
2024-11-01 12:17:06,881 [INFO] __main__: ICE connection state: checking
2024-11-01 12:17:06,905 [INFO] __main__: ICE connection state: completed
2024-11-01 12:17:06,911 [INFO] __main__: DataChannel is open
2024-11-01 12:17:06,911 [INFO] __main__: Interacting with Connector
2024-11-01 12:25:17,477 [INFO] __main__: DataChannel created, state: connecting
2024-11-01 12:25:19,534 [INFO] __main__: Closed aiohttp session
2024-11-01 12:25:35,354 [INFO] __main__: DataChannel created, state: connecting
2024-11-01 12:25:35,939 [INFO] __main__: Connected to signaling server
2024-11-01 12:25:41,133 [INFO] __main__: Offer sent to connector
2024-11-01 12:25:41,654 [INFO] __main__: Received answer from connector
2024-11-01 12:25:41,656 [INFO] __main__: ICE connection state: checking
2024-11-01 12:25:41,904 [ERROR] asyncio: Task exception was never retrieved
future: <Task finished name='Task-28' coro=<TurnClientMixin.send_data() done, defined at C:\Users\ASUS\AppData\Local\Programs\Python\Python311\Lib\site-packages\aioice\turn.py:271> exception=TransactionFailed(Message(message_method=Method.CHANNEL_BIND, message_class=Class.ERROR, transaction_id=b'\xbc\xd3N L\x92m`K\x11\x99\xc0'))>
Traceback (most recent call last):
  File "C:\Users\ASUS\AppData\Local\Programs\Python\Python311\Lib\site-packages\aioice\turn.py", line 290, in send_data
    await self.channel_bind(channel, addr)
  File "C:\Users\ASUS\AppData\Local\Programs\Python\Python311\Lib\site-packages\aioice\turn.py", line 111, in channel_bind
    await self.request_with_retry(request)
  File "C:\Users\ASUS\AppData\Local\Programs\Python\Python311\Lib\site-packages\aioice\turn.py", line 243, in request_with_retry
    response, addr = await self.request(request)
                     ^^^^^^^^^^^^^^^^^^^^^^^^^^^
  File "C:\Users\ASUS\AppData\Local\Programs\Python\Python311\Lib\site-packages\aioice\turn.py", line 230, in request
    return await transaction.run()
           ^^^^^^^^^^^^^^^^^^^^^^^
  File "C:\Users\ASUS\AppData\Local\Programs\Python\Python311\Lib\site-packages\aioice\stun.py", line 302, in run
    return await self.__future
           ^^^^^^^^^^^^^^^^^^^
aioice.stun.TransactionFailed: STUN transaction failed (401 - )
2024-11-01 12:25:42,242 [INFO] __main__: ICE connection state: completed
2024-11-01 12:25:43,194 [INFO] __main__: DataChannel is open
2024-11-01 12:25:43,196 [INFO] __main__: Interacting with Connector
2024-11-01 12:25:53,153 [INFO] __main__: Closed aiohttp session
2024-11-01 12:25:53,154 [ERROR] asyncio: Task exception was never retrieved
future: <Task finished name='Task-46' coro=<Client.interact_with_connector() done, defined at C:\Users\ASUS\OneDrive\Desktop\capstone1\ztatest1\client\client1.py:262> exception=EOFError()>
Traceback (most recent call last):
  File "C:\Users\ASUS\OneDrive\Desktop\capstone1\ztatest1\client\client1.py", line 269, in interact_with_connector
    choice = await aioconsole.ainput("Select an action: ")
             ^^^^^^^^^^^^^^^^^^^^^^^^^^^^^^^^^^^^^^^^^^^^^
  File "C:\Users\ASUS\AppData\Local\Programs\Python\Python311\Lib\site-packages\aioconsole\stream.py", line 297, in ainput
    raise EOFError
EOFError
2024-11-01 12:25:53,157 [INFO] __main__: ICE connection state: closed
2024-11-01 12:25:53,226 [ERROR] asyncio: Task was destroyed but it is pending!
task: <Task pending name='Task-51' coro=<RTCPeerConnection.close() running at C:\Users\ASUS\AppData\Local\Programs\Python\Python311\Lib\site-packages\aiortc\rtcpeerconnection.py:500> wait_for=<Future pending cb=[Task.task_wakeup()]>>
2024-11-01 12:25:53,227 [ERROR] asyncio: Task was destroyed but it is pending!
task: <Task pending name='Task-55' coro=<TurnClientMixin.delete() running at C:\Users\ASUS\AppData\Local\Programs\Python\Python311\Lib\site-packages\aioice\turn.py:188> wait_for=<Future pending cb=[Task.task_wakeup()]>>
2024-11-01 12:27:57,403 [INFO] __main__: DataChannel created, state: connecting
2024-11-01 12:27:57,997 [INFO] __main__: Connected to signaling server
2024-11-01 12:28:03,187 [INFO] __main__: Offer sent to connector
2024-11-01 12:28:03,697 [INFO] __main__: Received answer from connector
2024-11-01 12:28:03,699 [INFO] __main__: ICE connection state: checking
2024-11-01 12:28:03,939 [ERROR] asyncio: Task exception was never retrieved
future: <Task finished name='Task-28' coro=<TurnClientMixin.send_data() done, defined at C:\Users\ASUS\AppData\Local\Programs\Python\Python311\Lib\site-packages\aioice\turn.py:271> exception=TransactionFailed(Message(message_method=Method.CHANNEL_BIND, message_class=Class.ERROR, transaction_id=b'\x16\xe6\xc5\x8e0 \xad\t_WR\xfa'))>
Traceback (most recent call last):
  File "C:\Users\ASUS\AppData\Local\Programs\Python\Python311\Lib\site-packages\aioice\turn.py", line 290, in send_data
    await self.channel_bind(channel, addr)
  File "C:\Users\ASUS\AppData\Local\Programs\Python\Python311\Lib\site-packages\aioice\turn.py", line 111, in channel_bind
    await self.request_with_retry(request)
  File "C:\Users\ASUS\AppData\Local\Programs\Python\Python311\Lib\site-packages\aioice\turn.py", line 243, in request_with_retry
    response, addr = await self.request(request)
                     ^^^^^^^^^^^^^^^^^^^^^^^^^^^
  File "C:\Users\ASUS\AppData\Local\Programs\Python\Python311\Lib\site-packages\aioice\turn.py", line 230, in request
    return await transaction.run()
           ^^^^^^^^^^^^^^^^^^^^^^^
  File "C:\Users\ASUS\AppData\Local\Programs\Python\Python311\Lib\site-packages\aioice\stun.py", line 302, in run
    return await self.__future
           ^^^^^^^^^^^^^^^^^^^
aioice.stun.TransactionFailed: STUN transaction failed (401 - )
2024-11-01 12:28:04,381 [INFO] __main__: ICE connection state: completed
2024-11-01 12:28:05,150 [INFO] __main__: DataChannel is open
2024-11-01 12:28:05,152 [INFO] __main__: Interacting with Connector
2024-11-01 12:29:04,729 [INFO] __main__: Closed aiohttp session
2024-11-01 12:29:04,730 [ERROR] asyncio: Task exception was never retrieved
future: <Task finished name='Task-54' coro=<Client.interact_with_connector() done, defined at C:\Users\ASUS\OneDrive\Desktop\capstone1\ztatest1\client\client1.py:262> exception=EOFError()>
Traceback (most recent call last):
  File "C:\Users\ASUS\OneDrive\Desktop\capstone1\ztatest1\client\client1.py", line 269, in interact_with_connector
    choice = await aioconsole.ainput("Select an action: ")
             ^^^^^^^^^^^^^^^^^^^^^^^^^^^^^^^^^^^^^^^^^^^^^
  File "C:\Users\ASUS\AppData\Local\Programs\Python\Python311\Lib\site-packages\aioconsole\stream.py", line 297, in ainput
    raise EOFError
EOFError
2024-11-01 12:29:04,754 [INFO] __main__: ICE connection state: closed
2024-11-01 12:29:04,756 [ERROR] asyncio: Task was destroyed but it is pending!
task: <Task pending name='Task-98' coro=<TurnClientMixin.delete() running at C:\Users\ASUS\AppData\Local\Programs\Python\Python311\Lib\site-packages\aioice\turn.py:175>>
2024-11-01 12:29:04,860 [ERROR] asyncio: Task was destroyed but it is pending!
task: <Task pending name='Task-94' coro=<RTCPeerConnection.close() running at C:\Users\ASUS\AppData\Local\Programs\Python\Python311\Lib\site-packages\aiortc\rtcpeerconnection.py:500> wait_for=<Future pending cb=[Task.task_wakeup()]>>
2024-11-01 12:29:09,014 [INFO] __main__: DataChannel created, state: connecting
2024-11-01 12:29:09,622 [INFO] __main__: Connected to signaling server
2024-11-01 12:29:14,806 [INFO] __main__: Offer sent to connector
2024-11-01 12:29:15,004 [INFO] __main__: Received answer from connector
2024-11-01 12:29:15,005 [INFO] __main__: ICE connection state: checking
2024-11-01 12:29:15,247 [ERROR] asyncio: Task exception was never retrieved
future: <Task finished name='Task-28' coro=<TurnClientMixin.send_data() done, defined at C:\Users\ASUS\AppData\Local\Programs\Python\Python311\Lib\site-packages\aioice\turn.py:271> exception=TransactionFailed(Message(message_method=Method.CHANNEL_BIND, message_class=Class.ERROR, transaction_id=b'\xa6\xdf\xa2\xde\xfb9\xac\xe1S\x18\x8bP'))>
Traceback (most recent call last):
  File "C:\Users\ASUS\AppData\Local\Programs\Python\Python311\Lib\site-packages\aioice\turn.py", line 290, in send_data
    await self.channel_bind(channel, addr)
  File "C:\Users\ASUS\AppData\Local\Programs\Python\Python311\Lib\site-packages\aioice\turn.py", line 111, in channel_bind
    await self.request_with_retry(request)
  File "C:\Users\ASUS\AppData\Local\Programs\Python\Python311\Lib\site-packages\aioice\turn.py", line 243, in request_with_retry
    response, addr = await self.request(request)
                     ^^^^^^^^^^^^^^^^^^^^^^^^^^^
  File "C:\Users\ASUS\AppData\Local\Programs\Python\Python311\Lib\site-packages\aioice\turn.py", line 230, in request
    return await transaction.run()
           ^^^^^^^^^^^^^^^^^^^^^^^
  File "C:\Users\ASUS\AppData\Local\Programs\Python\Python311\Lib\site-packages\aioice\stun.py", line 302, in run
    return await self.__future
           ^^^^^^^^^^^^^^^^^^^
aioice.stun.TransactionFailed: STUN transaction failed (401 - )
2024-11-01 12:30:19,147 [INFO] __main__: ICE connection state: failed
2024-11-01 12:30:19,148 [ERROR] __main__: ICE connection failed, attempting reset
2024-11-01 12:30:19,149 [INFO] __main__: ICE connection state: closed
2024-11-01 12:30:19,204 [INFO] __main__: DataChannel created, state: connecting
2024-11-01 12:30:19,795 [INFO] __main__: Connected to signaling server
2024-11-01 12:30:24,968 [INFO] __main__: Offer sent to connector
2024-11-01 12:30:25,349 [INFO] __main__: Received answer from connector
2024-11-01 12:30:25,350 [INFO] __main__: ICE connection state: checking
2024-11-01 12:30:25,595 [ERROR] asyncio: Task exception was never retrieved
future: <Task finished name='Task-89' coro=<TurnClientMixin.send_data() done, defined at C:\Users\ASUS\AppData\Local\Programs\Python\Python311\Lib\site-packages\aioice\turn.py:271> exception=TransactionFailed(Message(message_method=Method.CHANNEL_BIND, message_class=Class.ERROR, transaction_id=b'\xfa\x8ei\xb8\xe3\x9e\xb4\xd8\x00{{\xc4'))>
Traceback (most recent call last):
  File "C:\Users\ASUS\AppData\Local\Programs\Python\Python311\Lib\site-packages\aioice\turn.py", line 290, in send_data
    await self.channel_bind(channel, addr)
  File "C:\Users\ASUS\AppData\Local\Programs\Python\Python311\Lib\site-packages\aioice\turn.py", line 111, in channel_bind
    await self.request_with_retry(request)
  File "C:\Users\ASUS\AppData\Local\Programs\Python\Python311\Lib\site-packages\aioice\turn.py", line 243, in request_with_retry
    response, addr = await self.request(request)
                     ^^^^^^^^^^^^^^^^^^^^^^^^^^^
  File "C:\Users\ASUS\AppData\Local\Programs\Python\Python311\Lib\site-packages\aioice\turn.py", line 230, in request
    return await transaction.run()
           ^^^^^^^^^^^^^^^^^^^^^^^
  File "C:\Users\ASUS\AppData\Local\Programs\Python\Python311\Lib\site-packages\aioice\stun.py", line 302, in run
    return await self.__future
           ^^^^^^^^^^^^^^^^^^^
aioice.stun.TransactionFailed: STUN transaction failed (401 - )
2024-11-01 12:30:26,047 [INFO] __main__: ICE connection state: completed
2024-11-01 12:30:26,814 [INFO] __main__: DataChannel is open
2024-11-01 12:30:26,815 [INFO] __main__: Interacting with Connector
2024-11-01 12:31:16,769 [INFO] __main__: Closed aiohttp session
2024-11-01 12:31:16,770 [ERROR] asyncio: Task exception was never retrieved
future: <Task finished name='Task-116' coro=<Client.interact_with_connector() done, defined at C:\Users\ASUS\OneDrive\Desktop\capstone1\ztatest1\client\client1.py:262> exception=EOFError()>
Traceback (most recent call last):
  File "C:\Users\ASUS\OneDrive\Desktop\capstone1\ztatest1\client\client1.py", line 269, in interact_with_connector
    choice = await aioconsole.ainput("Select an action: ")
             ^^^^^^^^^^^^^^^^^^^^^^^^^^^^^^^^^^^^^^^^^^^^^
  File "C:\Users\ASUS\AppData\Local\Programs\Python\Python311\Lib\site-packages\aioconsole\stream.py", line 297, in ainput
    raise EOFError
EOFError
2024-11-01 12:31:16,772 [INFO] __main__: Closed aiohttp session
2024-11-01 12:31:16,773 [INFO] __main__: ICE connection state: closed
2024-11-01 12:31:16,823 [ERROR] asyncio: Task was destroyed but it is pending!
task: <Task pending name='Task-143' coro=<RTCPeerConnection.close() running at C:\Users\ASUS\AppData\Local\Programs\Python\Python311\Lib\site-packages\aiortc\rtcpeerconnection.py:500> wait_for=<Future finished result=True>>
2024-11-01 12:31:16,826 [ERROR] asyncio: Unclosed client session
client_session: <aiohttp.client.ClientSession object at 0x00000205CB3D8150>
2024-11-01 13:09:47,942 [INFO] __main__: DataChannel created, state: connecting
2024-11-01 13:09:47,960 [INFO] __main__: Connected to signaling server
2024-11-01 13:09:53,236 [INFO] __main__: Offer sent to connector
2024-11-01 13:09:58,455 [INFO] __main__: Received answer from connector
2024-11-01 13:09:58,458 [INFO] __main__: ICE connection state: checking
2024-11-01 13:09:58,492 [INFO] __main__: ICE connection state: completed
2024-11-01 13:09:58,505 [INFO] __main__: DataChannel is open
2024-11-01 13:09:58,506 [INFO] __main__: Interacting with Connector
