2024-11-01 10:47:48,106 [INFO] __main__: DataChannel created, state: connecting
2024-11-01 10:47:48,696 [INFO] __main__: Connected to signaling server
2024-11-01 10:47:48,773 [INFO] __main__: Offer sent to connector
2024-11-01 10:47:48,970 [INFO] __main__: Received answer from connector
2024-11-01 10:47:48,971 [INFO] __main__: ICE connection state: checking
2024-11-01 10:48:52,803 [INFO] __main__: ICE connection state: failed
2024-11-01 10:48:52,803 [ERROR] __main__: ICE connection failed, attempting reset
2024-11-01 10:48:52,804 [INFO] __main__: ICE connection state: closed
2024-11-01 10:48:52,806 [INFO] __main__: DataChannel created, state: connecting
2024-11-01 10:48:53,417 [INFO] __main__: Connected to signaling server
2024-11-01 10:48:53,487 [INFO] __main__: Offer sent to connector
2024-11-01 10:48:53,697 [INFO] __main__: Received answer from connector
2024-11-01 10:48:53,698 [INFO] __main__: ICE connection state: checking
2024-11-01 10:49:57,578 [INFO] __main__: ICE connection state: failed
2024-11-01 10:49:57,579 [ERROR] __main__: ICE connection failed, attempting reset
2024-11-01 10:49:57,579 [INFO] __main__: ICE connection state: closed
2024-11-01 10:49:57,581 [INFO] __main__: DataChannel created, state: connecting
2024-11-01 10:49:58,150 [INFO] __main__: Connected to signaling server
2024-11-01 10:49:58,220 [INFO] __main__: Offer sent to connector
2024-11-01 10:49:58,414 [INFO] __main__: Received answer from connector
2024-11-01 10:49:58,415 [INFO] __main__: ICE connection state: checking
2024-11-01 10:50:31,144 [INFO] __main__: DataChannel created, state: connecting
2024-11-01 10:50:31,764 [INFO] __main__: Connected to signaling server
2024-11-01 10:50:31,842 [INFO] __main__: Offer sent to connector
2024-11-01 10:50:32,052 [INFO] __main__: Received answer from connector
2024-11-01 10:50:32,053 [INFO] __main__: ICE connection state: checking
2024-11-01 10:50:32,521 [INFO] __main__: ICE connection state: completed
2024-11-01 10:50:33,498 [INFO] __main__: DataChannel is now open
2024-11-01 10:50:33,499 [INFO] __main__: Interacting with Connector
2024-11-01 11:08:19,031 [ERROR] asyncio: Task exception was never retrieved
future: <Task finished name='Task-35' coro=<Client.interact_with_connector() done, defined at C:\Users\ASUS\OneDrive\Desktop\capstone1\ztatest1\client\client.py:187> exception=EOFError()>
Traceback (most recent call last):
  File "C:\Users\ASUS\OneDrive\Desktop\capstone1\ztatest1\client\client.py", line 194, in interact_with_connector
    choice = await aioconsole.ainput("Select an action: ")
             ^^^^^^^^^^^^^^^^^^^^^^^^^^^^^^^^^^^^^^^^^^^^^
  File "C:\Users\ASUS\AppData\Local\Programs\Python\Python311\Lib\site-packages\aioconsole\stream.py", line 297, in ainput
    raise EOFError
EOFError
2024-11-01 11:08:19,234 [INFO] __main__: DataChannel closed
2024-11-01 11:08:19,234 [INFO] __main__: ICE connection state: closed
2024-11-01 11:14:54,367 [INFO] __main__: DataChannel created, state: connecting
2024-11-01 11:14:54,981 [INFO] __main__: Connected to signaling server
2024-11-01 11:15:00,004 [INFO] __main__: Offer sent to connector
2024-11-01 11:15:00,056 [ERROR] asyncio: Unclosed client session
client_session: <aiohttp.client.ClientSession object at 0x000001D90818C210>
2024-11-01 11:15:19,704 [INFO] __main__: DataChannel created, state: connecting
2024-11-01 11:15:20,298 [INFO] __main__: Connected to signaling server
2024-11-01 11:15:25,319 [INFO] __main__: Offer sent to connector
2024-11-01 11:15:25,322 [INFO] __main__: Closed aiohttp session
2024-11-01 11:16:44,123 [INFO] __main__: DataChannel created, state: connecting
2024-11-01 11:16:44,132 [INFO] __main__: Connected to signaling server
2024-11-01 11:16:49,143 [INFO] __main__: Offer sent to connector
2024-11-01 11:16:49,146 [INFO] __main__: Closed aiohttp session
2024-11-01 11:19:31,766 [INFO] __main__: DataChannel created, state: connecting
2024-11-01 11:19:31,778 [INFO] __main__: Connected to signaling server
2024-11-01 11:19:36,805 [INFO] __main__: Offer sent to connector
2024-11-01 11:19:36,808 [INFO] __main__: Closed aiohttp session
2024-11-01 11:21:34,817 [INFO] __main__: DataChannel created, state: connecting
2024-11-01 11:21:34,826 [INFO] __main__: Connected to signaling server
2024-11-01 11:21:39,851 [INFO] __main__: Offer sent to connector
2024-11-01 11:22:41,396 [INFO] __main__: Closed aiohttp session
2024-11-01 11:22:43,188 [INFO] __main__: DataChannel created, state: connecting
2024-11-01 11:22:43,197 [INFO] __main__: Connected to signaling server
2024-11-01 11:22:48,205 [INFO] __main__: Offer sent to connector
2024-11-01 11:22:48,207 [ERROR] __main__: peer_info is missing 'ip' or 'port'
2024-11-01 11:22:53,228 [INFO] __main__: Received answer from connector
2024-11-01 11:22:53,229 [INFO] __main__: ICE connection state: checking
2024-11-01 11:22:53,256 [INFO] __main__: ICE connection state: completed
2024-11-01 11:22:53,262 [INFO] __main__: DataChannel is open
2024-11-01 11:22:53,263 [INFO] __main__: Interacting with Connector
2024-11-01 11:23:59,078 [INFO] __main__: Closed aiohttp session
2024-11-01 11:23:59,079 [ERROR] asyncio: Task exception was never retrieved
future: <Task finished name='Task-29' coro=<Client.interact_with_connector() done, defined at C:\Users\ASUS\OneDrive\Desktop\capstone1\ztatest1\client\client1.py:262> exception=EOFError()>
Traceback (most recent call last):
  File "C:\Users\ASUS\OneDrive\Desktop\capstone1\ztatest1\client\client1.py", line 269, in interact_with_connector
    choice = await aioconsole.ainput("Select an action: ")
             ^^^^^^^^^^^^^^^^^^^^^^^^^^^^^^^^^^^^^^^^^^^^^
  File "C:\Users\ASUS\AppData\Local\Programs\Python\Python311\Lib\site-packages\aioconsole\stream.py", line 297, in ainput
    raise EOFError
EOFError
2024-11-01 11:23:59,081 [INFO] __main__: ICE connection state: closed
2024-11-01 11:24:19,933 [INFO] __main__: DataChannel created, state: connecting
2024-11-01 11:24:19,942 [INFO] __main__: Connected to signaling server
2024-11-01 11:24:24,961 [INFO] __main__: Offer sent to connector
2024-11-01 11:24:24,963 [ERROR] __main__: peer_info is missing 'ip' or 'port'
2024-11-01 11:24:29,981 [INFO] __main__: Received answer from connector
2024-11-01 11:24:29,982 [INFO] __main__: ICE connection state: checking
2024-11-01 11:24:30,009 [INFO] __main__: ICE connection state: completed
2024-11-01 11:24:30,015 [INFO] __main__: DataChannel is open
2024-11-01 11:24:30,016 [INFO] __main__: Interacting with Connector
2024-11-01 11:25:04,390 [INFO] __main__: ICE connection state: closed
2024-11-01 11:25:10,763 [ERROR] asyncio: Task exception was never retrieved
future: <Task finished name='Task-29' coro=<Client.interact_with_connector() done, defined at C:\Users\ASUS\OneDrive\Desktop\capstone1\ztatest1\client\client1.py:262> exception=InvalidStateError()>
Traceback (most recent call last):
  File "C:\Users\ASUS\OneDrive\Desktop\capstone1\ztatest1\client\client1.py", line 273, in interact_with_connector
    self.channel.send(json.dumps(request))
  File "C:\Users\ASUS\AppData\Local\Programs\Python\Python311\Lib\site-packages\aiortc\rtcdatachannel.py", line 182, in send
    raise InvalidStateError
aiortc.exceptions.InvalidStateError
2024-11-01 11:25:12,762 [INFO] __main__: Closed aiohttp session
